<?xml version="1.0" encoding="utf-8"?>
<!-- This URDF was automatically created by SolidWorks to URDF Exporter! Originally created by Stephen Brawner (brawner@gmail.com) 
     Commit Version: 1.6.0-4-g7f85cfe  Build Version: 1.6.7995.38578
     For more information, please see http://wiki.ros.org/sw_urdf_exporter -->
<robot
  name="urdife">
  <link
    name="base_link">
    <inertial>
      <origin
        xyz="-0.11956 0.28002 -0.074943"
        rpy="0 0 0" />
      <mass
        value="0.051465" />
      <inertia
        ixx="0.00010641"
        ixy="-2.933E-07"
        ixz="-2.4366E-08"
        iyy="0.00014761"
        iyz="4.7194E-07"
        izz="0.00010682" />
    </inertial>
    <visual>
      <origin
        xyz="0 0 0"
        rpy="0 0 0" />
      <geometry>
        <mesh
          filename="package://urdife/meshes/base_link.STL" />
      </geometry>
      <material
        name="">
        <color
          rgba="0.79216 0.81961 0.93333 1" />
      </material>
    </visual>
    <collision>
      <origin
        xyz="0 0 0"
        rpy="0 0 0" />
      <geometry>
        <mesh
          filename="package://urdife/meshes/base_link.STL" />
      </geometry>
    </collision>
  </link>
  <link
    name="link_1">
    <inertial>
      <origin
        xyz="0.044112 0.0254 0.0053982"
        rpy="0 0 0" />
      <mass
        value="0.050423" />
      <inertia
        ixx="1.3732E-05"
        ixy="7.038E-11"
        ixz="5.1523E-07"
        iyy="2.9216E-05"
        iyz="1.7786E-11"
        izz="4.1856E-05" />
    </inertial>
    <visual>
      <origin
        xyz="0 0 0"
        rpy="0 0 0" />
      <geometry>
        <mesh
          filename="package://urdife/meshes/link_1.STL" />
      </geometry>
      <material
        name="">
        <color
          rgba="0.79216 0.81961 0.93333 1" />
      </material>
    </visual>
    <collision>
      <origin
        xyz="0 0 0"
        rpy="0 0 0" />
      <geometry>
        <mesh
          filename="package://urdife/meshes/link_1.STL" />
      </geometry>
    </collision>
  </link>
  <joint
    name="join_1"
    type="revolute">
    <origin
      xyz="-0.061706 0.054228 0.20834"
      rpy="-3.1416 0 -3.0527" />
    <parent
      link="base_link" />
    <child
      link="link_1" />
    <axis
      xyz="0 0 0" />
    <limit
      lower="0"
      upper="0"
      effort="0"
      velocity="0" />
  </joint>
  <link
    name="link_2">
    <inertial>
      <origin
        xyz="-1.197E-07 0.0028309 0.026779"
        rpy="0 0 0" />
      <mass
        value="0.044672" />
      <inertia
        ixx="5.7206E-05"
        ixy="-1.7014E-10"
        ixz="-7.1252E-11"
        iyy="5.4409E-05"
        iyz="1.0719E-06"
        izz="8.0654E-05" />
    </inertial>
    <visual>
      <origin
        xyz="0 0 0"
        rpy="0 0 0" />
      <geometry>
        <mesh
          filename="package://urdife/meshes/link_2.STL" />
      </geometry>
      <material
        name="">
        <color
          rgba="0.79216 0.81961 0.93333 1" />
      </material>
    </visual>
    <collision>
      <origin
        xyz="0 0 0"
        rpy="0 0 0" />
      <geometry>
        <mesh
          filename="package://urdife/meshes/link_2.STL" />
      </geometry>
    </collision>
  </link>
  <joint
    name="join_2"
    type="fixed">
    <origin
      xyz="0.0381 0.0254 0.05715"
      rpy="-1.5708 0 1.5708" />
    <parent
      link="link_1" />
    <child
      link="link_2" />
    <axis
      xyz="0 0 0" />
  </joint>
  <link
    name="link_3">
    <inertial>
      <origin
        xyz="0.17161 0.17839 -0.10482"
        rpy="0 0 0" />
      <mass
        value="0" />
      <inertia
        ixx="0"
        ixy="0"
        ixz="0"
        iyy="0"
        iyz="0"
        izz="0" />
    </inertial>
    <visual>
      <origin
        xyz="0 0 0"
        rpy="0 0 0" />
      <geometry>
        <mesh
          filename="package://urdife/meshes/link_3.STL" />
      </geometry>
      <material
        name="">
        <color
          rgba="0.79216 0.81961 0.93333 1" />
      </material>
    </visual>
    <collision>
      <origin
        xyz="0 0 0"
        rpy="0 0 0" />
      <geometry>
        <mesh
          filename="package://urdife/meshes/link_3.STL" />
      </geometry>
    </collision>
  </link>
  <joint
    name="join_3"
    type="revolute">
    <origin
      xyz="0.16112 -0.12382 -0.010076"
      rpy="-3.1416 0 -2.226" />
    <parent
      link="link_2" />
    <child
      link="link_3" />
    <axis
      xyz="0 0 0" />
    <limit
      lower="0"
      upper="0"
      effort="0"
      velocity="0" />
  </joint>
  <link
    name="link_4">
    <inertial>
      <origin
        xyz="-0.0059946 -2.616E-05 0.027858"
        rpy="0 0 0" />
      <mass
        value="0.021931" />
      <inertia
        ixx="1.4936E-05"
        ixy="-1.2507E-08"
        ixz="9.1978E-07"
        iyy="1.7274E-05"
        iyz="1.8662E-08"
        izz="1.9688E-05" />
    </inertial>
    <visual>
      <origin
        xyz="0 0 0"
        rpy="0 0 0" />
      <geometry>
        <mesh
          filename="package://urdife/meshes/link_4.STL" />
      </geometry>
      <material
        name="">
        <color
          rgba="0.79216 0.81961 0.93333 1" />
      </material>
    </visual>
    <collision>
      <origin
        xyz="0 0 0"
        rpy="0 0 0" />
      <geometry>
        <mesh
          filename="package://urdife/meshes/link_4.STL" />
      </geometry>
    </collision>
  </link>
  <joint
    name="join_4"
    type="fixed">
    <origin
      xyz="0 0 -0.00635"
      rpy="0 0 -1.5708" />
    <parent
      link="link_3" />
    <child
      link="link_4" />
    <axis
      xyz="0 0 0" />
  </joint>
  <link
    name="link_5">
    <inertial>
      <origin
        xyz="0.00446839525545415 -6.68313540685972E-06 0.104440745875309"
        rpy="0 0 0" />
      <mass
        value="0.0494145711938047" />
      <inertia
        ixx="0.000173085818089865"
        ixy="-4.5384317442674E-10"
        ixz="-1.15203565977359E-05"
        iyy="0.000171074328275662"
        iyz="9.98066618975896E-09"
        izz="1.84399451477666E-05" />
    </inertial>
    <visual>
      <origin
        xyz="0 0 0"
        rpy="0 0 0" />
      <geometry>
        <mesh
          filename="package://urdife/meshes/link_5.STL" />
      </geometry>
      <material
        name="">
        <color
          rgba="0.792156862745098 0.819607843137255 0.933333333333333 1" />
      </material>
    </visual>
    <collision>
      <origin
        xyz="0 0 0"
        rpy="0 0 0" />
      <geometry>
        <mesh
          filename="package://urdife/meshes/link_5.STL" />
      </geometry>
    </collision>
  </link>
  <joint
    name="joint_5"
    type="revolute">
    <origin
      xyz="-0.020179 -0.14978 -0.044358"
      rpy="-1.3654 -1.5708 -0.34916" />
    <parent
      link="link_4" />
    <child
      link="link_5" />
    <axis
      xyz="0 0 0" />
    <limit
      lower="0"
      upper="0"
      effort="0"
      velocity="0" />
  </joint>
  <link
    name="link_6">
    <inertial>
      <origin
        xyz="-1.88929013174854E-05 0.00405924531444479 0.0173889742033704"
        rpy="0 0 0" />
      <mass
        value="0.0118211467397755" />
      <inertia
        ixx="5.57038509842165E-06"
        ixy="2.1955646015406E-08"
        ixz="-1.69082490866416E-09"
        iyy="4.74088053048569E-06"
        iyz="-1.51697340694556E-07"
        izz="7.24397946196453E-06" />
    </inertial>
    <visual>
      <origin
        xyz="0 0 0"
        rpy="0 0 0" />
      <geometry>
        <mesh
          filename="package://urdife/meshes/link_6.STL" />
      </geometry>
      <material
        name="">
        <color
          rgba="0.792156862745098 0.819607843137255 0.933333333333333 1" />
      </material>
    </visual>
    <collision>
      <origin
        xyz="0 0 0"
        rpy="0 0 0" />
      <geometry>
        <mesh
          filename="package://urdife/meshes/link_6.STL" />
      </geometry>
    </collision>
  </link>
  <joint
    name="join_6"
    type="fixed">
    <origin
      xyz="0.012002 0 -0.02667"
      rpy="1.5708 0 -1.5708" />
    <parent
      link="link_5" />
    <child
      link="link_6" />
    <axis
      xyz="0 0 0" />
  </joint>
  <link
    name="link_7">
    <inertial>
      <origin
        xyz="-1.88951041850405E-05 0.00405926575451923 0.0173889821027933"
        rpy="0 0 0" />
      <mass
        value="0.0118211452654846" />
      <inertia
        ixx="5.57038515923717E-06"
        ixy="2.19534713312937E-08"
        ixz="-1.68922011393164E-09"
        iyy="4.7408795971409E-06"
        iyz="-1.51697740103605E-07"
        izz="7.24397926766796E-06" />
    </inertial>
    <visual>
      <origin
        xyz="0 0 0"
        rpy="0 0 0" />
      <geometry>
        <mesh
          filename="package://urdife/meshes/link_7.STL" />
      </geometry>
      <material
        name="">
        <color
          rgba="0.792156862745098 0.819607843137255 0.933333333333333 1" />
      </material>
    </visual>
    <collision>
      <origin
        xyz="0 0 0"
        rpy="0 0 0" />
      <geometry>
        <mesh
          filename="package://urdife/meshes/link_7.STL" />
      </geometry>
    </collision>
  </link>
  <joint
    name="join_7"
    type="revolute">
    <origin
      xyz="-0.011414 -0.0037077 -0.046124"
      rpy="1.5708 0 1.8849" />
    <parent
      link="link_6" />
    <child
      link="link_7" />
    <axis
      xyz="0 0 0" />
    <limit
      lower="0"
      upper="0"
      effort="0"
      velocity="0" />
  </joint>
  <link
    name="link_8">
    <inertial>
      <origin
        xyz="-1.8897E-05 0.0040593 0.017389"
        rpy="0 0 0" />
      <mass
        value="0.011821" />
      <inertia
        ixx="5.5704E-06"
        ixy="2.1955E-08"
        ixz="-1.6889E-09"
        iyy="4.7409E-06"
        iyz="-1.517E-07"
        izz="7.244E-06" />
    </inertial>
    <visual>
      <origin
        xyz="0 0 0"
        rpy="0 0 0" />
      <geometry>
        <mesh
          filename="package://urdife/meshes/link_8.STL" />
      </geometry>
      <material
        name="">
        <color
          rgba="0.79216 0.81961 0.93333 1" />
      </material>
    </visual>
    <collision>
      <origin
        xyz="0 0 0"
        rpy="0 0 0" />
      <geometry>
        <mesh
          filename="package://urdife/meshes/link_8.STL" />
      </geometry>
    </collision>
  </link>
  <joint
    name="join_8"
    type="revolute">
    <origin
      xyz="-0.010728 -0.0053805 -0.046124"
      rpy="1.5708 0 2.0357" />
    <parent
      link="link_7" />
    <child
      link="link_8" />
    <axis
      xyz="0 0 0" />
    <limit
      lower="0"
      upper="0"
      effort="0"
      velocity="0" />
  </joint>
  <link
    name="link_9">
    <inertial>
      <origin
        xyz="3.0927E-07 0.015804 -0.0071111"
        rpy="0 0 0" />
      <mass
        value="0.014234" />
      <inertia
        ixx="3.3183E-06"
        ixy="-4.3289E-10"
        ixz="1.5659E-10"
        iyy="1.5444E-06"
        iyz="1.1972E-06"
        izz="2.6396E-06" />
    </inertial>
    <visual>
      <origin
        xyz="0 0 0"
        rpy="0 0 0" />
      <geometry>
        <mesh
          filename="package://urdife/meshes/link_9.STL" />
      </geometry>
      <material
        name="">
        <color
          rgba="0.79216 0.81961 0.93333 1" />
      </material>
    </visual>
    <collision>
      <origin
        xyz="0 0 0"
        rpy="0 0 0" />
      <geometry>
        <mesh
          filename="package://urdife/meshes/link_9.STL" />
      </geometry>
    </collision>
  </link>
  <joint
    name="join_9"
    type="revolute">
    <origin
      xyz="-0.01669 -0.005178 -0.066634"
      rpy="-1.4779 0 -1.27" />
    <parent
      link="link_8" />
    <child
      link="link_9" />
    <axis
      xyz="0 0 0" />
    <limit
      lower="0"
      upper="0"
      effort="0"
      velocity="0" />
  </joint>
  <link
    name="link_10">
    <inertial>
      <origin
        xyz="1.7343E-06 0.015802 -0.0071107"
        rpy="0 0 0" />
      <mass
        value="0.014234" />
      <inertia
        ixx="3.3183E-06"
        ixy="-4.0789E-10"
        ixz="3.0188E-10"
        iyy="1.5444E-06"
        iyz="1.1971E-06"
        izz="2.6396E-06" />
    </inertial>
    <visual>
      <origin
        xyz="0 0 0"
        rpy="0 0 0" />
      <geometry>
        <mesh
          filename="package://urdife/meshes/link_10.STL" />
      </geometry>
      <material
        name="">
        <color
          rgba="0.79216 0.81961 0.93333 1" />
      </material>
    </visual>
    <collision>
      <origin
        xyz="0 0 0"
        rpy="0 0 0" />
      <geometry>
        <mesh
          filename="package://urdife/meshes/link_10.STL" />
      </geometry>
    </collision>
  </link>
  <joint
    name="join_10"
    type="revolute">
    <origin
      xyz="0 0.0032408 0.0348"
      rpy="-2.9559 0 3.1416" />
    <parent
      link="link_9" />
    <child
      link="link_10" />
    <axis
      xyz="0 0 0" />
    <limit
      lower="-1.57"
      upper="1.57"
      effort="10"
      velocity="50" />
  </joint>
</robot>